<?xml version="1.0" ?>
<!-- =================================================================================== -->
<!-- |    This document was autogenerated by xacro from /home/xzn/extreme-parkour/legged_gym/resources/robots/hustdog2/urdf/hustdog2.xacro | -->
<!-- |    EDITING THIS FILE BY HAND IS NOT RECOMMENDED                                 | -->
<!-- =================================================================================== -->
<robot name="hustdog2">
  <!-- alias for compatibility -->
  <material name="black">
    <color rgba="0.0 0.0 0.0 1.0"/>
  </material>
  <material name="blue">
    <color rgba="0.0 0.0 0.8 1.0"/>
  </material>
  <material name="green">
    <color rgba="0.0 0.8 0.0 1.0"/>
  </material>
  <material name="grey">
    <color rgba="0.2 0.2 0.2 1.0"/>
  </material>
  <material name="silver">
    <color rgba="0.9137254901960784 0.9137254901960784 0.8470588235294118 1.0"/>
  </material>
  <material name="orange">
    <color rgba="1.0 0.4235294117647059 0.0392156862745098 1.0"/>
  </material>
  <material name="brown">
    <color rgba="0.8705882352941177 0.8117647058823529 0.7647058823529411 1.0"/>
  </material>
  <material name="red">
    <color rgba="0.8 0.0 0.0 1.0"/>
  </material>
  <material name="white">
    <color rgba="1.0 1.0 1.0 1.0"/>
  </material>
  <!-- legnew.xacro: explicit per-leg definitions matching hustdog2.urdf values
       Each macro creates links/joints for one leg (hip -> thigh -> calf -> foot)
       Uses properties defined in const.xacro (hip_mass, hip_com_x, hip_link_length, thigh_length, calf_length, etc.)
  -->
  <!-- <xacro:include filename="$(find go1_gazebo)/launch/stairs.urdf.xacro"/> -->
  <link name="base_link">
    <visual>
      <origin rpy="0 0 0" xyz="0 0 0"/>
      <geometry>
        <box size="0.001 0.001 0.001"/>
      </geometry>
    </visual>
  </link>
  <joint name="base_link_to_trunk" type="fixed">
    <origin rpy="0 0 0" xyz="0 0 0"/>
    <parent link="base_link"/>
    <child link="trunk"/>
  </joint>
  <link name="trunk">
    <visual>
      <origin rpy="0 0 0" xyz="0 0 0"/>
      <geometry>
        <mesh filename="../meshes/trunk.STL" scale="1 1 1"/>
      </geometry>
      <!-- <material name="orange"/> -->
    </visual>
    <collision>
      <origin rpy="0 0 0" xyz="0.00014579412146028 -8.23603790256226e-05 0.0513141462721673"/>
      <geometry>
        <box size="0.3762 0.114 0.0935"/>
      </geometry>
    </collision>
    <inertial>
      <origin rpy="0 0 0" xyz="0.00014579412146028 -8.23603790256226e-05 0.0513141462721673"/>
      <mass value="3.304"/>
      <inertia ixx="0.00246223133481107" ixy="1.22541568850732e-07" ixz="-1.86486894267769e-09" iyy="0.00300451040783408" iyz="-5.45851421140666e-10" izz="0.00369726469403937"/>
    </inertial>
  </link>
  <!-- LIDAR (aligned to hustdog2.urdf) -->
  <link name="LIDAR">
    <inertial>
      <origin rpy="0 0 0" xyz="0.000199578579167744 5.56978729826113E-06 0.0930321007689041"/>
      <mass value="0.141887346048767"/>
      <inertia ixx="4.17977400205789E-05" ixy="-5.52625156952412E-09" ixz="-3.05328898604069E-07" iyy="4.50773279990884E-05" iyz="4.39725037239413E-10" izz="6.87998253582212E-05"/>
    </inertial>
    <visual>
      <origin rpy="0 0 0" xyz="0 0 0"/>
      <geometry>
        <mesh filename="../meshes/LIDAR.STL" scale="1 1 1"/>
      </geometry>
    </visual>
    <collision>
      <origin rpy="0 0 0" xyz="0.000199578579167744 5.56978729826113E-06 0.0930321007689041"/>
      <geometry>
        <cylinder length="0.04" radius="0.035"/>
      </geometry>
    </collision>
  </link>
  <joint name="LIDAR" type="fixed">
    <origin rpy="0 0 0" xyz="0 0 0"/>
    <parent link="trunk"/>
    <child link="LIDAR"/>
  </joint>
  <joint name="imu_joint" type="fixed">
    <parent link="trunk"/>
    <child link="imu_link"/>
    <origin rpy="0 0 0" xyz="-0.01592 -0.06659 -0.00617"/>
  </joint>
  <link name="imu_link">
    <inertial>
      <mass value="0.001"/>
      <origin rpy="0 0 0" xyz="0 0 0"/>
      <inertia ixx="0.0001" ixy="0" ixz="0" iyy="0.0001" iyz="0" izz="0.0001"/>
    </inertial>
    <visual>
      <origin rpy="0 0 0" xyz="0 0 0"/>
      <geometry>
        <box size="0.001 0.001 0.001"/>
      </geometry>
      <!-- <material name="red"/> -->
    </visual>
    <collision>
      <origin rpy="0 0 0" xyz="0 0 0"/>
      <geometry>
        <box size=".001 .001 .001"/>
      </geometry>
    </collision>
  </link>
  <!-- FR hip joint (from trunk to FR_hip) -->
  <joint name="FR_hip_joint" type="revolute">
    <origin rpy="0 0 0" xyz="0.1666 -0.051996 0.052"/>
    <parent link="trunk"/>
    <child link="FR_hip"/>
    <axis xyz="1 0 0"/>
    <dynamics damping="0.0" friction="0.0"/>
    <limit effort="23.7" lower="-0.6674139" upper="0.6674139" velocity="30.0"/>
  </joint>
  <link name="FR_hip">
    <visual>
      <origin rpy="0 0 0" xyz="0 0 0"/>
      <geometry>
        <mesh filename="../meshes/FR_hip.STL" scale="1 1 1"/>
      </geometry>
    </visual>
    <collision>
      <origin rpy="0 1.5707963267948966 0" xyz="0 0 0"/>
      <geometry>
        <cylinder length="0.04" radius="0.046"/>
      </geometry>
    </collision>
    <inertial>
      <origin rpy="0 0 0" xyz="0.061695 -0.00025557 7.6332e-05"/>
      <mass value="0.686"/>
      <inertia ixx="0.00015606" ixy="-9.8829e-08" ixz="3.6293e-07" iyy="0.00025823" iyz="3.0635e-08" izz="0.00014337"/>
    </inertial>
  </link>
  <!-- FR thigh joint (hip -> thigh) -->
  <joint name="FR_thigh_joint" type="revolute">
    <origin rpy="0 0 0" xyz="0.072 0 0"/>
    <parent link="FR_hip"/>
    <child link="FR_thigh"/>
    <axis xyz="0 1 0"/>
    <dynamics damping="0.0" friction="0.0"/>
    <limit effort="23.7" lower="-0.1309" upper="1.7017" velocity="30.0"/>
  </joint>
  <link name="FR_thigh">
    <visual>
      <origin rpy="0 0 0" xyz="0 0 0"/>
      <geometry>
        <mesh filename="../meshes/FR_thigh.STL" scale="1 1 1"/>
      </geometry>
    </visual>
    <collision>
      <origin rpy="1.5707963267948966 0 0" xyz="-0.00275078934112083 -0.061797306727413 -0.0009635539721171982"/>
      <geometry>
        <cylinder length="0.032" radius="0.041"/>
      </geometry>
    </collision>
    <collision>
      <origin rpy="0 0 0" xyz="-0.00275078934112083 -0.061797306727413 -0.0659635539721172"/>
      <geometry>
        <box size="0.0245 0.034 0.22"/>
      </geometry>
    </collision>
    <inertial>
      <origin rpy="0 0 0" xyz="-0.00275078934112083 -0.061797306727413 -0.0659635539721172"/>
      <mass value="1.027"/>
      <inertia ixx="0.000756603493555017" ixy="-7.92376228187542e-08" ixz="-4.17601614282535e-05" iyy="0.000910075280848094" iyz="-2.00894339422274e-08" izz="0.000175634171715802"/>
    </inertial>
  </link>
  <!-- FR calf joint (thigh -> calf) -->
  <joint name="FR_calf_joint" type="revolute">
    <origin rpy="0 0 0" xyz="0 0 -0.22"/>
    <parent link="FR_thigh"/>
    <child link="FR_calf"/>
    <axis xyz="0 1 0"/>
    <dynamics damping="0.0" friction="0.0"/>
    <limit effort="23.7" lower="-2.9123" upper="-1.2542" velocity="30.0"/>
  </joint>
  <link name="FR_calf">
    <visual>
      <origin rpy="0 0 0" xyz="0 0 0"/>
      <geometry>
        <mesh filename="../meshes/FR_calf.STL" scale="1 1 1"/>
      </geometry>
    </visual>
    <collision>
      <origin rpy="0 0 0" xyz="-0.000290700643747477 -0.0849759320544111 -0.0645449884848464"/>
      <geometry>
        <box size="0.016 0.016 0.22"/>
      </geometry>
    </collision>
    <inertial>
      <origin rpy="0 0 0" xyz="-0.000290700643747477 -0.0849759320544111 -0.0645449884848464"/>
      <mass value="0.249"/>
      <inertia ixx="0.000215077167464886" ixy="-1.03212973220742e-07" ixz="-7.20760001508999e-06" iyy="0.000218606842918735" iyz="-2.83504164955069e-06" izz="6.64639656615067e-06"/>
    </inertial>
  </link>
  <!-- FR foot -->
  <joint name="FR_foot_fixed" type="fixed">
    <origin rpy="0 0 0" xyz="-0.029484 0 -0.19799"/>
    <parent link="FR_calf"/>
    <child link="FR_foot"/>
  </joint>
  <link name="FR_foot">
    <visual>
      <origin rpy="0 0 0" xyz="0 0 0"/>
      <geometry>
        <mesh filename="../meshes/FR_foot.STL" scale="1 1 1"/>
      </geometry>
    </visual>
    <collision>
      <origin rpy="0 0 0" xyz="-0.004 -0.085 -0.003"/>
      <geometry>
        <sphere radius="0.02"/>
      </geometry>
    </collision>
    <inertial>
      <origin rpy="0 0 0" xyz="-0.00408434501666199 0.0851196204673925 -0.00290914827275929"/>
      <mass value="0.056"/>
      <inertia ixx="1.46759140000492e-05" ixy="-8.49482435630802e-08" ixz="3.07254971706503e-06" iyy="1.27945976674806e-05" iyz="-3.13456863350562e-08" izz="1.40635378188276e-05"/>
    </inertial>
  </link>
  <!-- FL hip -->
  <joint name="FL_hip_joint" type="revolute">
    <origin rpy="0 0 0" xyz="0.1666 0.051996 0.052"/>
    <parent link="trunk"/>
    <child link="FL_hip"/>
    <axis xyz="1 0 0"/>
    <dynamics damping="0.0" friction="0.0"/>
    <limit effort="23.7" lower="-0.6674139" upper="0.6674139" velocity="30.0"/>
  </joint>
  <link name="FL_hip">
    <visual>
      <origin rpy="0 0 0" xyz="0 0 0"/>
      <geometry>
        <mesh filename="../meshes/FL_hip.STL" scale="1 1 1"/>
      </geometry>
    </visual>
    <collision>
      <origin rpy="0 1.5707963267948966 0" xyz="0 0 0"/>
      <geometry>
        <cylinder length="0.04" radius="0.046"/>
      </geometry>
    </collision>
    <inertial>
      <origin rpy="0 0 0" xyz="0.061695 0.00025557 7.6332e-05"/>
      <mass value="0.686"/>
      <inertia ixx="0.00015606" ixy="-9.8829e-08" ixz="3.6293e-07" iyy="0.00025823" iyz="3.0635e-08" izz="0.00014337"/>
    </inertial>
  </link>
  <!-- thigh -->
  <joint name="FL_thigh_joint" type="revolute">
    <origin rpy="0 0 0" xyz="0.072 0 0"/>
    <parent link="FL_hip"/>
    <child link="FL_thigh"/>
    <axis xyz="0 1 0"/>
    <dynamics damping="0.0" friction="0.0"/>
    <limit effort="23.7" lower="-0.1309" upper="1.7017" velocity="30.0"/>
  </joint>
  <link name="FL_thigh">
    <visual>
      <origin rpy="0 0 0" xyz="0 0 0"/>
      <geometry>
        <mesh filename="../meshes/FL_thigh.STL" scale="1 1 1"/>
      </geometry>
    </visual>
    <collision>
      <origin rpy="1.5707963267948966 0 0" xyz="-0.00275078934112083 0.061797306727413 -0.0009635539721171982"/>
      <geometry>
        <cylinder length="0.032" radius="0.041"/>
      </geometry>
    </collision>
    <collision>
      <origin rpy="0 0 0" xyz="-0.00275078934112083 0.061797306727413 -0.0659635539721172"/>
      <geometry>
        <box size="0.0245 0.034 0.22"/>
      </geometry>
    </collision>
    <inertial>
      <origin rpy="0 0 0" xyz="-0.00275078934112083 0.061797306727413 -0.0659635539721172"/>
      <mass value="1.027"/>
      <inertia ixx="0.000756603493555017" ixy="-7.92376228187542e-08" ixz="-4.17601614282535e-05" iyy="0.000910075280848094" iyz="-2.00894339422274e-08" izz="0.000175634171715802"/>
    </inertial>
  </link>
  <!-- calf -->
  <joint name="FL_calf_joint" type="revolute">
    <origin rpy="0 0 0" xyz="0 0 -0.22"/>
    <parent link="FL_thigh"/>
    <child link="FL_calf"/>
    <axis xyz="0 1 0"/>
    <dynamics damping="0.0" friction="0.0"/>
    <limit effort="23.7" lower="-2.9123" upper="-1.2542" velocity="30.0"/>
  </joint>
  <link name="FL_calf">
    <visual>
      <origin rpy="0 0 0" xyz="0 0 0"/>
      <geometry>
        <mesh filename="../meshes/FL_calf.STL" scale="1 1 1"/>
      </geometry>
    </visual>
    <collision>
      <origin rpy="0 0 0" xyz="-0.000290700643747477 0.0849759320544111 -0.0645449884848464"/>
      <geometry>
        <box size="0.016 0.016 0.22"/>
      </geometry>
    </collision>
    <inertial>
      <origin rpy="0 0 0" xyz="-0.000290700643747477 0.0849759320544111 -0.0645449884848464"/>
      <mass value="0.249"/>
      <inertia ixx="0.000215077167464886" ixy="-1.03212973220742e-07" ixz="-7.20760001508999e-06" iyy="0.000218606842918735" iyz="-2.83504164955069e-06" izz="6.64639656615067e-06"/>
    </inertial>
  </link>
  <joint name="FL_foot_fixed" type="fixed">
    <origin rpy="0 0 0" xyz="-0.029481 0 -0.19799"/>
    <parent link="FL_calf"/>
    <child link="FL_foot"/>
  </joint>
  <link name="FL_foot">
    <visual>
      <origin rpy="0 0 0" xyz="0 0 0"/>
      <geometry>
        <mesh filename="../meshes/FL_foot.STL" scale="1 1 1"/>
      </geometry>
    </visual>
    <collision>
      <origin rpy="0 0 0" xyz="-0.004 0.085 -0.003"/>
      <geometry>
        <sphere radius="0.02"/>
      </geometry>
    </collision>
    <inertial>
      <origin rpy="0 0 0" xyz="-0.00408434501666199 -0.0851196204673925 -0.00290914827275929"/>
      <mass value="0.056"/>
      <inertia ixx="1.46759140000492e-05" ixy="-8.49482435630802e-08" ixz="3.07254971706503e-06" iyy="1.27945976674806e-05" iyz="-3.13456863350562e-08" izz="1.40635378188276e-05"/>
    </inertial>
  </link>
  <joint name="RR_hip_joint" type="revolute">
    <origin rpy="0 0 0" xyz="-0.1666 -0.051996 0.052"/>
    <parent link="trunk"/>
    <child link="RR_hip"/>
    <axis xyz="1 0 0"/>
    <dynamics damping="0.0" friction="0.0"/>
    <limit effort="23.7" lower="-0.6674139" upper="0.6674139" velocity="30.0"/>
  </joint>
  <link name="RR_hip">
    <visual>
      <origin rpy="3.141592653589793 0 0" xyz="0 0 0"/>
      <geometry>
        <mesh filename="../meshes/RR_hip.STL" scale="1 1 1"/>
      </geometry>
    </visual>
    <collision>
      <origin rpy="0 1.5707963267948966 0" xyz="0 0 0"/>
      <geometry>
        <cylinder length="0.04" radius="0.046"/>
      </geometry>
    </collision>
    <inertial>
      <origin rpy="0 0 0" xyz="0.061695 -0.00025557 7.6332e-05"/>
      <mass value="0.686"/>
      <inertia ixx="0.00015606" ixy="-9.8829e-08" ixz="3.6293e-07" iyy="0.00025823" iyz="3.0635e-08" izz="0.00014337"/>
    </inertial>
  </link>
  <joint name="RR_thigh_joint" type="revolute">
    <origin rpy="0 0 0" xyz="-0.072 0 0"/>
    <parent link="RR_hip"/>
    <child link="RR_thigh"/>
    <axis xyz="0 1 0"/>
    <dynamics damping="0.0" friction="0.0"/>
    <limit effort="23.7" lower="-0.1309" upper="1.7017" velocity="30.0"/>
  </joint>
  <link name="RR_thigh">
    <visual>
      <origin rpy="0 0 0" xyz="0 0 0"/>
      <geometry>
        <mesh filename="../meshes/RR_thigh.STL" scale="1 1 1"/>
      </geometry>
    </visual>
    <collision>
      <origin rpy="1.5707963267948966 0 0" xyz="-0.00275078934112083 -0.061797306727413 -0.0009635539721171982"/>
      <geometry>
        <cylinder length="0.032" radius="0.041"/>
      </geometry>
    </collision>
    <collision>
      <origin rpy="0 0 0" xyz="-0.00275078934112083 -0.061797306727413 -0.0659635539721172"/>
      <geometry>
        <box size="0.0245 0.034 0.22"/>
      </geometry>
    </collision>
    <inertial>
      <origin rpy="0 0 0" xyz="-0.00275078934112083 -0.061797306727413 -0.0659635539721172"/>
      <mass value="1.027"/>
      <inertia ixx="0.000756603493555017" ixy="-7.92376228187542e-08" ixz="-4.17601614282535e-05" iyy="0.000910075280848094" iyz="-2.00894339422274e-08" izz="0.000175634171715802"/>
    </inertial>
  </link>
  <joint name="RR_calf_joint" type="revolute">
    <origin rpy="0 0 0" xyz="0 0 -0.22"/>
    <parent link="RR_thigh"/>
    <child link="RR_calf"/>
    <axis xyz="0 1 0"/>
    <dynamics damping="0.0" friction="0.0"/>
    <limit effort="23.7" lower="-2.9123" upper="-1.2542" velocity="30.0"/>
  </joint>
  <link name="RR_calf">
    <visual>
      <origin rpy="0 0 0" xyz="0 0 0"/>
      <geometry>
        <mesh filename="../meshes/RR_calf.STL" scale="1 1 1"/>
      </geometry>
    </visual>
    <collision>
      <origin rpy="0 0 0" xyz="-0.000290700643747477 -0.0849759320544111 -0.0645449884848464"/>
      <geometry>
        <box size="0.016 0.016 0.22"/>
      </geometry>
    </collision>
    <inertial>
      <origin rpy="0 0 0" xyz="-0.000290700643747477 -0.0849759320544111 -0.0645449884848464"/>
      <mass value="0.249"/>
      <inertia ixx="0.000215077167464886" ixy="-1.03212973220742e-07" ixz="-7.20760001508999e-06" iyy="0.000218606842918735" iyz="-2.83504164955069e-06" izz="6.64639656615067e-06"/>
    </inertial>
  </link>
  <joint name="RR_foot_fixed" type="fixed">
    <origin rpy="0 0 0" xyz="-0.029484 0 -0.19799"/>
    <parent link="RR_calf"/>
    <child link="RR_foot"/>
  </joint>
  <link name="RR_foot">
    <visual>
      <origin rpy="0 0 0" xyz="0 0 0"/>
      <geometry>
        <mesh filename="../meshes/RR_foot.STL" scale="1 1 1"/>
      </geometry>
    </visual>
    <collision>
      <origin rpy="0 0 0" xyz="-0.004 -0.085 -0.003"/>
      <!-- RR (Right Rear) foot offset: Y is negative? -->
      <geometry>
        <sphere radius="0.02"/>
      </geometry>
    </collision>
    <inertial>
      <origin rpy="0 0 0" xyz="-0.00408434501666199 0.0851196204673925 -0.00290914827275929"/>
      <mass value="0.056"/>
      <inertia ixx="1.46759140000492e-05" ixy="-8.49482435630802e-08" ixz="3.07254971706503e-06" iyy="1.27945976674806e-05" iyz="-3.13456863350562e-08" izz="1.40635378188276e-05"/>
    </inertial>
  </link>
  <joint name="RL_hip_joint" type="revolute">
    <origin rpy="0 0 0" xyz="-0.1666 0.051996 0.052"/>
    <parent link="trunk"/>
    <child link="RL_hip"/>
    <axis xyz="1 0 0"/>
    <dynamics damping="0.0" friction="0.0"/>
    <limit effort="23.7" lower="-0.6674139" upper="0.6674139" velocity="30.0"/>
  </joint>
  <link name="RL_hip">
    <visual>
      <origin rpy="0 0 0" xyz="0 0 0"/>
      <geometry>
        <mesh filename="../meshes/RL_hip.STL" scale="1 1 1"/>
      </geometry>
    </visual>
    <collision>
      <origin rpy="0 1.5707963267948966 0" xyz="0 0 0"/>
      <geometry>
        <cylinder length="0.04" radius="0.046"/>
      </geometry>
    </collision>
    <inertial>
      <origin rpy="0 0 0" xyz="0.061695 0.00025557 7.6332e-05"/>
      <mass value="0.686"/>
      <inertia ixx="0.00015606" ixy="-9.8829e-08" ixz="3.6293e-07" iyy="0.00025823" iyz="3.0635e-08" izz="0.00014337"/>
    </inertial>
  </link>
  <joint name="RL_thigh_joint" type="revolute">
    <origin rpy="0 0 0" xyz="-0.072 0 0"/>
    <parent link="RL_hip"/>
    <child link="RL_thigh"/>
    <axis xyz="0 1 0"/>
    <dynamics damping="0.0" friction="0.0"/>
    <limit effort="23.7" lower="-0.1309" upper="1.7017" velocity="30.0"/>
  </joint>
  <link name="RL_thigh">
    <visual>
      <origin rpy="0 0 0" xyz="0 0 0"/>
      <geometry>
        <mesh filename="../meshes/RL_thigh.STL" scale="1 1 1"/>
      </geometry>
    </visual>
    <collision>
      <origin rpy="1.5707963267948966 0 0" xyz="-0.00275078934112083 0.061797306727413 -0.0009635539721171982"/>
      <geometry>
        <cylinder length="0.032" radius="0.041"/>
      </geometry>
    </collision>
    <collision>
      <origin rpy="0 0 0" xyz="-0.00275078934112083 0.061797306727413 -0.0659635539721172"/>
      <geometry>
        <box size="0.0245 0.034 0.22"/>
      </geometry>
    </collision>
    <inertial>
      <origin rpy="0 0 0" xyz="-0.00275078934112083 0.061797306727413 -0.0659635539721172"/>
      <mass value="1.027"/>
      <inertia ixx="0.000756603493555017" ixy="-7.92376228187542e-08" ixz="-4.17601614282535e-05" iyy="0.000910075280848094" iyz="-2.00894339422274e-08" izz="0.000175634171715802"/>
    </inertial>
  </link>
  <joint name="RL_calf_joint" type="revolute">
    <origin rpy="0 0 0" xyz="0 0 -0.22"/>
    <parent link="RL_thigh"/>
    <child link="RL_calf"/>
    <axis xyz="0 1 0"/>
    <dynamics damping="0.0" friction="0.0"/>
    <limit effort="23.7" lower="-2.9123" upper="-1.2542" velocity="30.0"/>
  </joint>
  <link name="RL_calf">
    <visual>
      <origin rpy="0 0 0" xyz="0 0 0"/>
      <geometry>
        <mesh filename="../meshes/RL_calf.STL" scale="1 1 1"/>
      </geometry>
    </visual>
    <collision>
      <origin rpy="0 0 0" xyz="-0.000290700643747477 0.0849759320544111 -0.0645449884848464"/>
      <geometry>
        <box size="0.016 0.016 0.22"/>
      </geometry>
    </collision>
    <inertial>
      <origin rpy="0 0 0" xyz="-0.000290700643747477 0.0849759320544111 -0.0645449884848464"/>
      <mass value="0.249"/>
      <inertia ixx="0.000215077167464886" ixy="-1.03212973220742e-07" ixz="-7.20760001508999e-06" iyy="0.000218606842918735" iyz="-2.83504164955069e-06" izz="6.64639656615067e-06"/>
    </inertial>
  </link>
  <joint name="RL_foot_fixed" type="fixed">
    <origin rpy="0 0 0" xyz="-0.029481 0 -0.19799"/>
    <parent link="RL_calf"/>
    <child link="RL_foot"/>
  </joint>
  <link name="RL_foot">
    <visual>
      <origin rpy="0 0 0" xyz="0 0 0"/>
      <geometry>
        <mesh filename="../meshes/RL_foot.STL" scale="1 1 1"/>
      </geometry>
    </visual>
    <collision>
      <origin rpy="0 0 0" xyz="-0.004 0.085 -0.003"/>
      <geometry>
        <sphere radius="0.02"/>
      </geometry>
    </collision>
    <inertial>
      <origin rpy="0 0 0" xyz="-0.00408434501666199 0.0851196204673925 -0.00290914827275929"/>
      <mass value="0.056"/>
      <inertia ixx="1.46759140000492e-05" ixy="-8.49482435630802e-08" ixz="3.07254971706503e-06" iyy="1.27945976674806e-05" iyz="-3.13456863350562e-08" izz="1.40635378188276e-05"/>
    </inertial>
  </link>
  <joint name="camera_joint_CAMERA" type="fixed">
    <origin rpy="0 0 0" xyz="0.1775 0.0 0.1195004"/>
    <parent link="trunk"/>
    <child link="camera_CAMERA"/>
  </joint>
  <link name="camera_CAMERA">
    <collision>
      <origin rpy="0 0 0" xyz="0 0 0"/>
      <geometry>
        <box size=".001 .001 .001"/>
      </geometry>
    </collision>
    <visual>
      <origin rpy="0 0 0" xyz="-0.1775 -0.0 -0.1195004"/>
      <geometry>
        <!-- ORIGINAL: Lidar mesh kept as comment for safety -->
        <!-- <mesh filename="../meshes/Lidar.STL" scale="1 1 1"/> -->
        <!-- Use CAMERA mesh for depth camera visuals -->
        <mesh filename="../meshes/CAMERA.STL" scale="1 1 1"/>
      </geometry>
    </visual>
    <inertial>
      <mass value="1e-5"/>
      <origin rpy="0 0 0" xyz="0 0 0"/>
      <inertia ixx="1e-6" ixy="0" ixz="0" iyy="1e-6" iyz="0" izz="1e-6"/>
    </inertial>
  </link>
  <joint name="camera_optical_joint_CAMERA" type="fixed">
    <origin rpy="-1.5707963267948966 0 -1.5707963267948966" xyz="0 0 0"/>
    <parent link="camera_CAMERA"/>
    <child link="camera_optical_CAMERA"/>
  </joint>
  <link name="camera_optical_CAMERA">
        </link>
  <gazebo reference="camera_CAMERA">
    <!-- <material>Gazebo/Black</material> -->
    <sensor name="camera_CAMERA_camera" type="depth">
      <update_rate>16</update_rate>
      <camera>
        <horizontal_fov>2.094</horizontal_fov>
        <image>
          <width>928</width>
          <height>800</height>
          <format>R8G8B8</format>
        </image>
        <clip>
          <near>0.1</near>
          <far>5</far>
        </clip>
      </camera>
      <plugin filename="libgazebo_ros_openni_kinect.so" name="camera_CAMERA_controller">
        <baseline>0.025</baseline>
        <alwaysOn>true</alwaysOn>
        <updateRate>0.0</updateRate>
        <cameraName>camera_CAMERA_ir</cameraName>
        <imageTopicName>/camera_CAMERA/color/image_raw</imageTopicName>
        <cameraInfoTopicName>/camera_CAMERA/color/camera_info</cameraInfoTopicName>
        <depthImageTopicName>/camera_CAMERA/depth/image_raw</depthImageTopicName>
        <depthImageInfoTopicName>/camera_CAMERA/depth/camera_info</depthImageInfoTopicName>
        <pointCloudTopicName>/cam1/point_cloud_CAMERA</pointCloudTopicName>
        <frameName>camera_optical_CAMERA</frameName>
        <pointCloudCutoff>0.1</pointCloudCutoff>
        <pointCloudCutoffMax>1.5</pointCloudCutoffMax>
        <distortionK1>0.0</distortionK1>
        <distortionK2>0.0</distortionK2>
        <distortionK3>0.0</distortionK3>
        <distortionT1>0.0</distortionT1>
        <distortionT2>0.0</distortionT2>
        <CxPrime>0</CxPrime>
        <Cx>0.0045</Cx>
        <Cy>0.0039</Cy>
        <focalLength>0</focalLength>
        <hackBaseline>0</hackBaseline>
      </plugin>
    </sensor>
  </gazebo>
  <!-- <joint name="camera_laserscan_joint_left" type="fixed">
        <origin rpy="0 0.2618 0" xyz="0 0 0"/>
        <parent link="camera_CAMERA"/>
        <child link="camera_laserscan_link_left"/>
    </joint>

    <link name="camera_laserscan_link_left">
    </link> -->
  <!-- 
    <joint name="camera_laserscan_joint_right" type="fixed">
        <origin rpy="0 0 0" xyz="0 0 0"/>
        <parent link="camera_CAMERA"/>
        <child link="camera_laserscan_link_right"/>
    </joint>

    <link name="camera_laserscan_link_right">
    </link> -->
  <!-- <xacro:ultraSound name="left" origin_rpy="0 0.2618 ${PI/2}" origin_xyz="-0.0535  0.0826 0.00868"/>

    <xacro:ultraSound name="right" origin_rpy="0 0.2618 ${-PI/2}" origin_xyz="-0.0535 -0.0826 0.00868"/>

    <xacro:ultraSound name="face" origin_rpy="0 0 0" origin_xyz="0.2747 0.0 -0.0088"/> -->
</robot>
